2018-02-13 22:43:00,570 ERROR: Exception on /index [GET] [in /home/tk/PycharmProjects/microblog/venv/local/lib/python2.7/site-packages/flask/app.py:1560]
Traceback (most recent call last):
  File "/home/tk/PycharmProjects/microblog/venv/local/lib/python2.7/site-packages/flask/app.py", line 1982, in wsgi_app
    response = self.full_dispatch_request()
  File "/home/tk/PycharmProjects/microblog/venv/local/lib/python2.7/site-packages/flask/app.py", line 1614, in full_dispatch_request
    rv = self.handle_user_exception(e)
  File "/home/tk/PycharmProjects/microblog/venv/local/lib/python2.7/site-packages/flask/app.py", line 1517, in handle_user_exception
    reraise(exc_type, exc_value, tb)
  File "/home/tk/PycharmProjects/microblog/venv/local/lib/python2.7/site-packages/flask/app.py", line 1610, in full_dispatch_request
    rv = self.preprocess_request()
  File "/home/tk/PycharmProjects/microblog/venv/local/lib/python2.7/site-packages/flask/app.py", line 1831, in preprocess_request
    rv = func()
  File "/home/tk/PycharmProjects/microblog/app/routes.py", line 12, in before_request
    if current_user.is_authenticated:
  File "/home/tk/PycharmProjects/microblog/venv/local/lib/python2.7/site-packages/werkzeug/local.py", line 347, in __getattr__
    return getattr(self._get_current_object(), name)
  File "/home/tk/PycharmProjects/microblog/venv/local/lib/python2.7/site-packages/werkzeug/local.py", line 306, in _get_current_object
    return self.__local()
  File "/home/tk/PycharmProjects/microblog/venv/local/lib/python2.7/site-packages/flask_login/utils.py", line 26, in <lambda>
    current_user = LocalProxy(lambda: _get_user())
  File "/home/tk/PycharmProjects/microblog/venv/local/lib/python2.7/site-packages/flask_login/utils.py", line 335, in _get_user
    current_app.login_manager._load_user()
  File "/home/tk/PycharmProjects/microblog/venv/local/lib/python2.7/site-packages/flask_login/login_manager.py", line 359, in _load_user
    return self.reload_user()
  File "/home/tk/PycharmProjects/microblog/venv/local/lib/python2.7/site-packages/flask_login/login_manager.py", line 321, in reload_user
    user = self.user_callback(user_id)
  File "/home/tk/PycharmProjects/microblog/app/models.py", line 28, in load_user
    return User.query.get(int(id))
  File "/home/tk/PycharmProjects/microblog/venv/local/lib/python2.7/site-packages/flask_sqlalchemy/__init__.py", line 512, in __get__
    mapper = orm.class_mapper(type)
  File "/home/tk/PycharmProjects/microblog/venv/local/lib/python2.7/site-packages/sqlalchemy/orm/base.py", line 421, in class_mapper
    mapper = _inspect_mapped_class(class_, configure=configure)
  File "/home/tk/PycharmProjects/microblog/venv/local/lib/python2.7/site-packages/sqlalchemy/orm/base.py", line 400, in _inspect_mapped_class
    mapper._configure_all()
  File "/home/tk/PycharmProjects/microblog/venv/local/lib/python2.7/site-packages/sqlalchemy/orm/mapper.py", line 1268, in _configure_all
    configure_mappers()
  File "/home/tk/PycharmProjects/microblog/venv/local/lib/python2.7/site-packages/sqlalchemy/orm/mapper.py", line 3013, in configure_mappers
    mapper._post_configure_properties()
  File "/home/tk/PycharmProjects/microblog/venv/local/lib/python2.7/site-packages/sqlalchemy/orm/mapper.py", line 1811, in _post_configure_properties
    prop.init()
  File "/home/tk/PycharmProjects/microblog/venv/local/lib/python2.7/site-packages/sqlalchemy/orm/interfaces.py", line 184, in init
    self.do_init()
  File "/home/tk/PycharmProjects/microblog/venv/local/lib/python2.7/site-packages/sqlalchemy/orm/relationships.py", line 1655, in do_init
    self._process_dependent_arguments()
  File "/home/tk/PycharmProjects/microblog/venv/local/lib/python2.7/site-packages/sqlalchemy/orm/relationships.py", line 1712, in _process_dependent_arguments
    self.target = self.mapper.mapped_table
  File "/home/tk/PycharmProjects/microblog/venv/local/lib/python2.7/site-packages/sqlalchemy/util/langhelpers.py", line 767, in __get__
    obj.__dict__[self.__name__] = result = self.fget(obj)
  File "/home/tk/PycharmProjects/microblog/venv/local/lib/python2.7/site-packages/sqlalchemy/orm/relationships.py", line 1628, in mapper
    argument = self.argument()
  File "/home/tk/PycharmProjects/microblog/venv/local/lib/python2.7/site-packages/sqlalchemy/ext/declarative/clsregistry.py", line 281, in __call__
    x = eval(self.arg, globals(), self._dict)
  File "<string>", line 1, in <module>
  File "/home/tk/PycharmProjects/microblog/venv/local/lib/python2.7/site-packages/sqlalchemy/util/_collections.py", line 729, in __missing__
    self[key] = val = self.creator(key)
  File "/home/tk/PycharmProjects/microblog/venv/local/lib/python2.7/site-packages/sqlalchemy/ext/declarative/clsregistry.py", line 262, in _access_cls
    return _determine_container(key, cls._decl_class_registry[key])
  File "/home/tk/PycharmProjects/microblog/venv/local/lib/python2.7/site-packages/sqlalchemy/ext/declarative/clsregistry.py", line 246, in _determine_container
    value = value.attempt_get([], key)
  File "/home/tk/PycharmProjects/microblog/venv/local/lib/python2.7/site-packages/sqlalchemy/ext/declarative/clsregistry.py", line 91, in attempt_get
    (".".join(path + [key]))
InvalidRequestError: Multiple classes found for path "User" in the registry of this declarative base. Please use a fully module-qualified path.
2018-02-13 22:43:00,836 ERROR: Exception on /favicon.ico [GET] [in /home/tk/PycharmProjects/microblog/venv/local/lib/python2.7/site-packages/flask/app.py:1560]
Traceback (most recent call last):
  File "/home/tk/PycharmProjects/microblog/venv/local/lib/python2.7/site-packages/flask/app.py", line 1982, in wsgi_app
    response = self.full_dispatch_request()
  File "/home/tk/PycharmProjects/microblog/venv/local/lib/python2.7/site-packages/flask/app.py", line 1614, in full_dispatch_request
    rv = self.handle_user_exception(e)
  File "/home/tk/PycharmProjects/microblog/venv/local/lib/python2.7/site-packages/flask/app.py", line 1517, in handle_user_exception
    reraise(exc_type, exc_value, tb)
  File "/home/tk/PycharmProjects/microblog/venv/local/lib/python2.7/site-packages/flask/app.py", line 1610, in full_dispatch_request
    rv = self.preprocess_request()
  File "/home/tk/PycharmProjects/microblog/venv/local/lib/python2.7/site-packages/flask/app.py", line 1831, in preprocess_request
    rv = func()
  File "/home/tk/PycharmProjects/microblog/app/routes.py", line 12, in before_request
    if current_user.is_authenticated:
  File "/home/tk/PycharmProjects/microblog/venv/local/lib/python2.7/site-packages/werkzeug/local.py", line 347, in __getattr__
    return getattr(self._get_current_object(), name)
  File "/home/tk/PycharmProjects/microblog/venv/local/lib/python2.7/site-packages/werkzeug/local.py", line 306, in _get_current_object
    return self.__local()
  File "/home/tk/PycharmProjects/microblog/venv/local/lib/python2.7/site-packages/flask_login/utils.py", line 26, in <lambda>
    current_user = LocalProxy(lambda: _get_user())
  File "/home/tk/PycharmProjects/microblog/venv/local/lib/python2.7/site-packages/flask_login/utils.py", line 335, in _get_user
    current_app.login_manager._load_user()
  File "/home/tk/PycharmProjects/microblog/venv/local/lib/python2.7/site-packages/flask_login/login_manager.py", line 359, in _load_user
    return self.reload_user()
  File "/home/tk/PycharmProjects/microblog/venv/local/lib/python2.7/site-packages/flask_login/login_manager.py", line 321, in reload_user
    user = self.user_callback(user_id)
  File "/home/tk/PycharmProjects/microblog/app/models.py", line 28, in load_user
    return User.query.get(int(id))
  File "/home/tk/PycharmProjects/microblog/venv/local/lib/python2.7/site-packages/flask_sqlalchemy/__init__.py", line 512, in __get__
    mapper = orm.class_mapper(type)
  File "/home/tk/PycharmProjects/microblog/venv/local/lib/python2.7/site-packages/sqlalchemy/orm/base.py", line 421, in class_mapper
    mapper = _inspect_mapped_class(class_, configure=configure)
  File "/home/tk/PycharmProjects/microblog/venv/local/lib/python2.7/site-packages/sqlalchemy/orm/base.py", line 400, in _inspect_mapped_class
    mapper._configure_all()
  File "/home/tk/PycharmProjects/microblog/venv/local/lib/python2.7/site-packages/sqlalchemy/orm/mapper.py", line 1268, in _configure_all
    configure_mappers()
  File "/home/tk/PycharmProjects/microblog/venv/local/lib/python2.7/site-packages/sqlalchemy/orm/mapper.py", line 3010, in configure_mappers
    raise e
InvalidRequestError: One or more mappers failed to initialize - can't proceed with initialization of other mappers. Triggering mapper: 'Mapper|User|user'. Original exception was: Multiple classes found for path "User" in the registry of this declarative base. Please use a fully module-qualified path.
2018-02-13 22:45:34,836 INFO: Microblog startup [in /home/tk/PycharmProjects/microblog/app/__init__.py:41]
2018-02-13 22:46:23,934 INFO: Microblog startup [in /home/tk/PycharmProjects/microblog/app/__init__.py:41]
2018-02-13 22:47:27,944 INFO: Microblog startup [in /home/tk/PycharmProjects/microblog/app/__init__.py:41]
2018-02-13 22:55:42,044 INFO: Microblog startup [in /home/tk/PycharmProjects/microblog/app/__init__.py:41]
2018-02-13 23:03:14,967 INFO: Microblog startup [in /home/tk/PycharmProjects/microblog/app/__init__.py:41]
2018-02-13 23:06:44,641 INFO: Microblog startup [in /home/tk/PycharmProjects/microblog/app/__init__.py:41]
2018-02-13 23:41:46,086 INFO: Microblog startup [in /home/tk/PycharmProjects/microblog/app/__init__.py:41]
2018-02-13 23:46:53,934 INFO: Microblog startup [in /home/tk/PycharmProjects/microblog/app/__init__.py:41]
2018-02-13 23:46:58,345 INFO: Microblog startup [in /home/tk/PycharmProjects/microblog/app/__init__.py:41]
2018-02-13 23:48:12,828 INFO: Microblog startup [in /home/tk/PycharmProjects/microblog/app/__init__.py:41]
2018-02-13 23:54:52,517 INFO: Microblog startup [in /home/tk/PycharmProjects/microblog/app/__init__.py:41]
2018-02-13 23:56:54,786 INFO: Microblog startup [in /home/tk/PycharmProjects/microblog/app/__init__.py:41]
2018-02-14 00:12:40,616 INFO: Microblog startup [in /home/tk/PycharmProjects/microblog/app/__init__.py:41]
